La risposta breve è: **no, non sono uguali**:

La differenza è che se un errore accade in `f1`, allora è gestito da`.catch` qui:

```js run
promise
  .then(f1)
  .catch(f2);
```

...Ma non qui:

```js run
promise
  .then(f1, f2);
```

Questo perché un errore è passato giù nella catena, e nel secondo pezzo di codice non c'è una catena sotto`f1`.

In altre parole, `.then` passa i risultati/errori al prossimo `.then/catch`. Così nel primo esempio, c'è un `catch` sotto, e nel secondo -- non c'è, così l'errore non è gestito.
